File: data/input/M-35Zr39Ti25Nb_Glb_11/stage_35Zr39Ti25Nb_2019_05_17_15_07.txt
Project Title : exSitu_35Zr39Ti25Nb
Material : 35Zr39Ti25Nb
Informations :
Date : 17/05/2019
Type test : Tension / Compression
Control Mod : Manual
Section : Rectangular
Width(mm) : 2.210000
Total Length(mm) : 50.000000
Gauge Length(mm) : 5.100000
Thickness(mm) : 0.950000
====================================================================================================
Time (s) 	Speed (µm/s) 	Traverse Speed (µm/s) 	Displacement (µm) 	Force (N) 	Real Speed (µm/s) 	Cal. Force (V) 	Stress (Mpa) 	Elongation (%) 	Speed Controller Input Voltage (V)
0.100000 	5.000000 	5.000000 	-543.100000 	4.821489 	0.007756 	2.462335 	2.296494 	-10.649020 	1.377600
0.600000 	5.000000 	5.000000 	-543.100000 	5.186305 	0.005760 	2.462639 	2.470257 	-10.649020 	1.377600
1.100000 	5.000000 	5.000000 	-543.100000 	5.215885 	0.006551 	2.462663 	2.484346 	-10.649020 	1.377600
1.600000 	5.000000 	5.000000 	-543.100000 	4.998967 	0.007268 	2.462483 	2.381027 	-10.649020 	1.377600
2.100000 	5.000000 	5.000000 	-543.100000 	4.693310 	0.006700 	2.462228 	2.235442 	-10.649020 	1.377600
2.600000 	5.000000 	5.000000 	-543.100000 	4.880648 	0.006179 	2.462384 	2.324672 	-10.649020 	1.377600
3.100000 	5.000000 	5.000000 	-543.100000 	4.791909 	0.009449 	2.462310 	2.282405 	-10.649020 	1.377600
3.600000 	5.000000 	5.000000 	-543.100000 	4.870788 	0.008163 	2.462376 	2.319975 	-10.649020 	1.377600
4.100000 	5.000000 	5.000000 	-543.100000 	5.127146 	0.008117 	2.462589 	2.442079 	-10.649020 	1.377600
4.600000 	5.000000 	5.000000 	-543.100000 	5.048266 	0.007855 	2.462524 	2.404509 	-10.649020 	1.377600
5.100000 	5.000000 	5.000000 	-543.100000 	5.018687 	0.006551 	2.462499 	2.390420 	-10.649020 	1.377600
5.600000 	5.000000 	5.000000 	-543.100000 	4.801769 	0.008312 	2.462318 	2.287101 	-10.649020 	1.377600
6.100000 	5.000000 	5.000000 	-543.100000 	4.900368 	0.008237 	2.462400 	2.334064 	-10.649020 	1.377600
6.600000 	5.000000 	5.000000 	-543.100000 	5.097566 	0.007857 	2.462565 	2.427990 	-10.649020 	1.377600
7.100000 	5.000000 	5.000000 	-543.100000 	4.949667 	0.005880 	2.462442 	2.357546 	-10.649020 	1.377600
7.600000 	5.000000 	5.000000 	-543.100000 	5.531401 	0.006347 	2.462926 	2.634628 	-10.649020 	1.377600
8.100000 	5.000000 	5.000000 	-543.100000 	5.038406 	0.008639 	2.462515 	2.399813 	-10.649020 	1.377600
8.600000 	5.000000 	5.000000 	-543.100000 	5.146865 	0.005387 	2.462606 	2.451472 	-10.649020 	1.377600
9.100000 	5.000000 	5.000000 	-543.100000 	4.604571 	0.007754 	2.462154 	2.193175 	-10.649020 	1.377600
9.600000 	5.000000 	5.000000 	-543.100000 	5.107426 	0.007203 	2.462573 	2.432687 	-10.649020 	1.377600
10.100000 	5.000000 	5.000000 	-543.100000 	5.215885 	0.005890 	2.462663 	2.484346 	-10.649020 	1.377600
10.600000 	5.000000 	5.000000 	-543.100000 	4.851068 	0.007763 	2.462359 	2.310583 	-10.649020 	1.377600
11.100000 	5.000000 	5.000000 	-543.100000 	5.265184 	0.007987 	2.462704 	2.507828 	-10.649020 	1.377600
11.600000 	5.000000 	5.000000 	-543.100000 	5.127146 	0.007838 	2.462589 	2.442079 	-10.649020 	1.377600
12.100000 	5.000000 	5.000000 	-543.100000 	4.880648 	0.005555 	2.462384 	2.324672 	-10.649020 	1.377600
12.600000 	5.000000 	5.000000 	-543.200000 	4.949667 	0.006366 	2.462442 	2.357546 	-10.650980 	1.377600
13.100000 	5.000000 	5.000000 	-543.100000 	4.939808 	0.007884 	2.462433 	2.352850 	-10.649020 	1.377600
13.600000 	5.000000 	5.000000 	-543.200000 	4.772189 	0.007446 	2.462294 	2.273012 	-10.650980 	1.377600
14.100000 	5.000000 	5.000000 	-543.200000 	4.890508 	0.006505 	2.462392 	2.329368 	-10.650980 	1.377600
14.600000 	5.000000 	5.000000 	-543.200000 	5.028547 	0.006907 	2.462507 	2.395116 	-10.650980 	1.377600
15.100000 	5.000000 	5.000000 	-543.200000 	4.939808 	0.007475 	2.462433 	2.352850 	-10.650980 	1.377600
15.600000 	5.000000 	5.000000 	-543.200000 	5.097566 	0.006953 	2.462565 	2.427990 	-10.650980 	1.377600
16.100000 	5.000000 	5.000000 	-543.200000 	4.880648 	0.005257 	2.462384 	2.324672 	-10.650980 	1.377600
16.600000 	5.000000 	5.000000 	-543.200000 	5.235604 	0.007111 	2.462680 	2.493739 	-10.650980 	1.377600
17.100000 	5.000000 	5.000000 	-543.200000 	5.058126 	0.007148 	2.462532 	2.409205 	-10.650980 	1.377600
17.600000 	5.000000 	5.000000 	-543.200000 	4.693310 	0.006058 	2.462228 	2.235442 	-10.650980 	1.377600
18.100000 	5.000000 	5.000000 	-543.200000 	4.870788 	0.007633 	2.462376 	2.319975 	-10.650980 	1.377600
18.600000 	5.000000 	5.000000 	-543.200000 	4.801769 	0.009813 	2.462318 	2.287101 	-10.650980 	1.377600
19.100000 	5.000000 	5.000000 	-543.200000 	5.087706 	0.006785 	2.462557 	2.423294 	-10.650980 	1.377600
19.600000 	5.000000 	5.000000 	-543.200000 	4.880648 	0.007203 	2.462384 	2.324672 	-10.650980 	1.377600
20.100000 	5.000000 	5.000000 	-543.200000 	5.265184 	0.006878 	2.462704 	2.507828 	-10.650980 	1.377600
20.600000 	5.000000 	5.000000 	-543.200000 	4.663730 	0.006467 	2.462203 	2.221353 	-10.650980 	1.377600
21.100000 	5.000000 	5.000000 	-543.200000 	5.117286 	0.006467 	2.462581 	2.437383 	-10.650980 	1.377600
21.600000 	5.000000 	5.000000 	-543.200000 	5.028547 	0.007018 	2.462507 	2.395116 	-10.650980 	1.377600
22.100000 	5.000000 	5.000000 	-543.200000 	4.772189 	0.007232 	2.462294 	2.273012 	-10.650980 	1.377600
22.600000 	5.000000 	5.000000 	-543.200000 	4.703170 	0.008341 	2.462236 	2.240138 	-10.650980 	1.377600
23.100000 	5.000000 	5.000000 	-543.200000 	5.383503 	0.006440 	2.462803 	2.564183 	-10.650980 	1.377600
23.600000 	5.000000 	5.000000 	-543.200000 	4.979247 	0.006905 	2.462466 	2.371635 	-10.650980 	1.377600
24.100000 	5.000000 	5.000000 	-543.200000 	4.989107 	0.008620 	2.462474 	2.376331 	-10.650980 	1.377600
24.600000 	5.000000 	5.000000 	-543.200000 	5.314484 	0.007475 	2.462746 	2.531309 	-10.650980 	1.377600
25.100000 	5.000000 	5.000000 	-543.200000 	5.551121 	0.006700 	2.462943 	2.644020 	-10.650980 	1.377600
25.600000 	5.000000 	5.000000 	-543.200000 	4.742610 	0.008062 	2.462269 	2.258923 	-10.650980 	1.377600
26.100000 	5.000000 	5.000000 	-543.200000 	4.713030 	0.007540 	2.462244 	2.244834 	-10.650980 	1.377600
26.600000 	5.000000 	5.000000 	-543.200000 	4.456673 	0.008610 	2.462031 	2.122730 	-10.650980 	1.377600
27.100000 	5.000000 	5.000000 	-543.200000 	4.900368 	0.009421 	2.462400 	2.334064 	-10.650980 	1.377600
27.600000 	5.000000 	5.000000 	-543.200000 	4.703170 	0.008302 	2.462236 	2.240138 	-10.650980 	1.377600
28.100000 	5.000000 	5.000000 	-543.200000 	5.087706 	0.007297 	2.462557 	2.423294 	-10.650980 	1.377600
28.600000 	5.000000 	5.000000 	-543.200000 	5.048266 	0.007073 	2.462524 	2.404509 	-10.650980 	1.377600
29.100000 	5.000000 	5.000000 	-543.200000 	5.048266 	0.008136 	2.462524 	2.404509 	-10.650980 	1.377600
29.600000 	5.000000 	5.000000 	-543.200000 	4.998967 	0.008610 	2.462483 	2.381027 	-10.650980 	1.377600
30.100000 	5.000000 	5.000000 	-543.200000 	4.969387 	0.007725 	2.462458 	2.366938 	-10.650980 	1.377600
30.600000 	5.000000 	5.000000 	-543.200000 	5.107426 	0.010101 	2.462573 	2.432687 	-10.650980 	1.377600
31.100000 	5.000000 	5.000000 	-543.200000 	4.860928 	0.008367 	2.462368 	2.315279 	-10.650980 	1.377600
31.600000 	5.000000 	5.000000 	-543.200000 	5.077846 	0.009952 	2.462548 	2.418598 	-10.650980 	1.377600
32.100000 	5.000000 	5.000000 	-543.200000 	4.989107 	0.006616 	2.462474 	2.376331 	-10.650980 	1.377600
32.600000 	5.000000 	5.000000 	-543.200000 	4.811629 	0.009589 	2.462327 	2.291798 	-10.650980 	1.377600
33.100000 	5.000000 	5.000000 	-543.200000 	4.890508 	0.008377 	2.462392 	2.329368 	-10.650980 	1.377600
33.600000 	5.000000 	5.000000 	-543.200000 	5.156725 	0.009300 	2.462614 	2.456168 	-10.650980 	1.377600
34.100000 	5.000000 	5.000000 	-543.200000 	4.979247 	0.009291 	2.462466 	2.371635 	-10.650980 	1.377600
34.600000 	5.000000 	5.000000 	-543.200000 	4.979247 	0.007157 	2.462466 	2.371635 	-10.650980 	1.377600
35.100000 	5.000000 	5.000000 	-543.200000 	4.289054 	0.010334 	2.461891 	2.042893 	-10.650980 	1.377600
35.600000 	5.000000 	5.000000 	-543.200000 	4.910228 	0.008172 	2.462409 	2.338761 	-10.650980 	1.377600
36.100000 	5.000000 	5.000000 	-543.200000 	4.870788 	0.010428 	2.462376 	2.319975 	-10.650980 	1.377600
36.600000 	5.000000 	5.000000 	-543.200000 	4.880648 	0.008834 	2.462384 	2.324672 	-10.650980 	1.377600
37.100000 	5.000000 	5.000000 	-543.200000 	4.920088 	0.007585 	2.462417 	2.343457 	-10.650980 	1.377600
37.600000 	5.000000 	5.000000 	-543.200000 	5.107426 	0.009077 	2.462573 	2.432687 	-10.650980 	1.377600
38.100000 	5.000000 	5.000000 	-543.200000 	5.087706 	0.006020 	2.462557 	2.423294 	-10.650980 	1.377600
38.600000 	5.000000 	5.000000 	-543.200000 	5.186305 	0.004995 	2.462639 	2.470257 	-10.650980 	1.377600
39.100000 	5.000000 	5.000000 	-543.200000 	4.722890 	0.007259 	2.462253 	2.249531 	-10.650980 	1.377600
39.600000 	5.000000 	5.000000 	-543.200000 	5.245464 	0.007102 	2.462688 	2.498435 	-10.650980 	1.377600
40.100000 	5.000000 	5.000000 	-543.200000 	5.156725 	0.008107 	2.462614 	2.456168 	-10.650980 	1.377600
40.600000 	5.000000 	5.000000 	-543.200000 	5.186305 	0.008192 	2.462639 	2.470257 	-10.650980 	1.377600
41.100000 	5.000000 	5.000000 	-543.200000 	5.156725 	0.008807 	2.462614 	2.456168 	-10.650980 	1.377600
41.600000 	5.000000 	5.000000 	-543.200000 	4.811629 	0.008107 	2.462327 	2.291798 	-10.650980 	1.377600
42.100000 	5.000000 	5.000000 	-543.200000 	4.989107 	0.008107 	2.462474 	2.376331 	-10.650980 	1.377600
42.600000 	5.000000 	5.000000 	-543.200000 	5.284904 	0.007176 	2.462721 	2.517220 	-10.650980 	1.377600
43.100000 	5.000000 	5.000000 	-543.200000 	4.782049 	0.006114 	2.462302 	2.277709 	-10.650980 	1.377600
43.600000 	5.000000 	5.000000 	-543.200000 	5.067986 	0.006188 	2.462540 	2.413901 	-10.650980 	1.377600
44.100000 	5.000000 	5.000000 	-543.200000 	4.624291 	0.007893 	2.462170 	2.202568 	-10.650980 	1.377600
44.600000 	5.000000 	5.000000 	-543.200000 	5.048266 	0.007268 	2.462524 	2.404509 	-10.650980 	1.377600
45.100000 	5.000000 	5.000000 	-543.200000 	4.791909 	0.008098 	2.462310 	2.282405 	-10.650980 	1.377600
45.600000 	5.000000 	5.000000 	-543.200000 	4.989107 	0.006393 	2.462474 	2.376331 	-10.650980 	1.377600
46.100000 	5.000000 	5.000000 	-543.200000 	5.067986 	0.008117 	2.462540 	2.413901 	-10.650980 	1.377600
46.600000 	5.000000 	5.000000 	-543.200000 	4.584851 	0.009495 	2.462138 	2.183782 	-10.650980 	1.377600
47.100000 	5.000000 	5.000000 	-543.200000 	4.969387 	0.006328 	2.462458 	2.366938 	-10.650980 	1.377600
47.600000 	5.000000 	5.000000 	-543.200000 	4.989107 	0.006291 	2.462474 	2.376331 	-10.650980 	1.377600
48.100000 	5.000000 	5.000000 	-543.200000 	4.920088 	0.007391 	2.462417 	2.343457 	-10.650980 	1.377600
48.600000 	5.000000 	5.000000 	-543.200000 	4.505972 	0.008461 	2.462072 	2.146212 	-10.650980 	1.377600
49.100000 	5.000000 	5.000000 	-543.200000 	4.722890 	0.008973 	2.462253 	2.249531 	-10.650980 	1.377600
49.600000 	5.000000 	5.000000 	-543.200000 	4.880648 	0.005620 	2.462384 	2.324672 	-10.650980 	1.377600
50.100000 	5.000000 	5.000000 	-543.200000 	4.910228 	0.007287 	2.462409 	2.338761 	-10.650980 	1.377600
50.600000 	5.000000 	5.000000 	-543.200000 	4.693310 	0.008629 	2.462228 	2.235442 	-10.650980 	1.377600
51.100000 	5.000000 	5.000000 	-543.200000 	5.255324 	0.007912 	2.462696 	2.503131 	-10.650980 	1.377600
51.600000 	5.000000 	5.000000 	-543.200000 	4.929948 	0.007083 	2.462425 	2.348153 	-10.650980 	1.377600
52.100000 	5.000000 	5.000000 	-543.200000 	4.574991 	0.008350 	2.462129 	2.179086 	-10.650980 	1.377600
52.600000 	5.000000 	5.000000 	-543.200000 	5.146865 	0.007744 	2.462606 	2.451472 	-10.650980 	1.377600
53.100000 	5.000000 	5.000000 	-543.200000 	4.949667 	0.007251 	2.462442 	2.357546 	-10.650980 	1.377600
53.600000 	5.000000 	5.000000 	-543.200000 	5.058126 	0.008117 	2.462532 	2.409205 	-10.650980 	1.377600
54.100000 	5.000000 	5.000000 	-543.100000 	4.535552 	0.500806 	2.462096 	2.160301 	-10.649020 	1.377600
54.600000 	5.000000 	5.000000 	-543.000000 	5.038406 	4.932665 	2.462515 	2.399813 	-10.647059 	1.377600
55.100000 	5.000000 	5.000000 	-542.900000 	5.787759 	4.971732 	2.463140 	2.756732 	-10.645098 	1.377600
55.600000 	5.000000 	5.000000 	-542.900000 	5.689160 	4.978144 	2.463058 	2.709769 	-10.645098 	1.377600
56.100000 	5.000000 	5.000000 	-542.800000 	5.639860 	4.982542 	2.463017 	2.686287 	-10.643137 	1.377600
56.600000 	5.000000 	5.000000 	-542.900000 	5.383503 	4.973372 	2.462803 	2.564183 	-10.645098 	1.377600
57.100000 	5.000000 	5.000000 	-542.800000 	5.817338 	4.973372 	2.463165 	2.770821 	-10.643137 	1.377600
57.600000 	5.000000 	5.000000 	-542.800000 	5.275044 	4.980828 	2.462713 	2.512524 	-10.643137 	1.377600
58.100000 	5.000000 	5.000000 	-542.900000 	5.689160 	4.972925 	2.463058 	2.709769 	-10.645098 	1.377600
58.600000 	5.000000 	5.000000 	-542.900000 	5.906077 	4.969942 	2.463239 	2.813088 	-10.645098 	1.377600
59.100000 	5.000000 	5.000000 	-542.900000 	5.984956 	4.975683 	2.463304 	2.850658 	-10.645098 	1.377600
59.600000 	5.000000 	5.000000 	-542.900000 	5.344063 	4.976056 	2.462770 	2.545398 	-10.645098 	1.377600
60.100000 	5.000000 	5.000000 	-542.900000 	5.906077 	4.971732 	2.463239 	2.813088 	-10.645098 	1.377600
60.600000 	5.000000 	5.000000 	-542.900000 	5.156725 	4.967482 	2.462614 	2.456168 	-10.645098 	1.377600
61.100000 	5.000000 	5.000000 	-542.900000 	5.511681 	4.967109 	2.462910 	2.625235 	-10.645098 	1.377600
61.600000 	5.000000 	5.000000 	-543.000000 	5.442662 	4.977696 	2.462852 	2.592361 	-10.647059 	1.377600
62.100000 	5.000000 	5.000000 	-543.000000 	5.077846 	4.975236 	2.462548 	2.418598 	-10.647059 	1.377600
62.600000 	5.000000 	5.000000 	-543.100000 	5.067986 	4.974192 	2.462540 	2.413901 	-10.649020 	1.377600
63.100000 	5.000000 	5.000000 	-543.000000 	5.738459 	4.977696 	2.463099 	2.733250 	-10.647059 	1.377600
63.600000 	5.000000 	5.000000 	-542.800000 	5.866638 	4.974267 	2.463206 	2.794302 	-10.643137 	1.377600
64.100000 	5.000000 	5.000000 	-542.600000 	6.172294 	4.982542 	2.463460 	2.939888 	-10.639216 	1.377600
64.600000 	5.000000 	5.000000 	-542.400000 	6.744168 	4.978367 	2.463937 	3.212274 	-10.635294 	1.377600
65.100000 	5.000000 	5.000000 	-542.100000 	6.763888 	4.970539 	2.463953 	3.221666 	-10.629412 	1.377600
65.600000 	5.000000 	5.000000 	-541.700000 	7.404781 	4.980157 	2.464487 	3.526926 	-10.621569 	1.377600
66.100000 	5.000000 	5.000000 	-541.400000 	7.759738 	4.975161 	2.464783 	3.695993 	-10.615686 	1.377600
66.600000 	5.000000 	5.000000 	-540.900000 	7.868196 	4.973894 	2.464874 	3.747652 	-10.605882 	1.377600
67.100000 	5.000000 	5.000000 	-540.500000 	8.410491 	4.979113 	2.465326 	4.005949 	-10.598039 	1.377600
67.600000 	5.000000 	5.000000 	-540.200000 	8.686568 	4.974192 	2.465556 	4.137446 	-10.592157 	1.377600
68.100000 	5.000000 	5.000000 	-540.000000 	9.169703 	4.972030 	2.465958 	4.367565 	-10.588235 	1.377600
68.600000 	5.000000 	5.000000 	-539.800000 	9.662697 	4.973521 	2.466369 	4.602380 	-10.584314 	1.377600
69.100000 	5.000000 	5.000000 	-539.500000 	10.096533 	4.972552 	2.466731 	4.809018 	-10.578431 	1.377600
69.600000 	5.000000 	5.000000 	-539.100000 	11.013503 	4.977547 	2.467495 	5.245774 	-10.570588 	1.377600
70.100000 	5.000000 	5.000000 	-538.700000 	12.226270 	4.975460 	2.468505 	5.823420 	-10.562745 	1.377600
70.600000 	5.000000 	5.000000 	-538.400000 	12.650246 	4.969421 	2.468859 	6.025361 	-10.556863 	1.377600
71.100000 	5.000000 	5.000000 	-538.200000 	14.188389 	4.970166 	2.470140 	6.757985 	-10.552941 	1.377600
71.600000 	5.000000 	5.000000 	-538.000000 	15.095500 	4.974639 	2.470896 	7.190045 	-10.549020 	1.377600
72.100000 	5.000000 	5.000000 	-537.800000 	15.913871 	4.978442 	2.471578 	7.579838 	-10.545098 	1.377600
72.600000 	5.000000 	5.000000 	-538.500000 	16.288547 	4.972477 	2.471891 	7.758298 	-10.558824 	1.377600
73.100000 	5.000000 	5.000000 	-538.200000 	16.919580 	4.970315 	2.472416 	8.058862 	-10.552941 	1.377600
73.600000 	5.000000 	5.000000 	-538.000000 	17.057619 	4.971359 	2.472532 	8.124610 	-10.549020 	1.377600
74.100000 	5.000000 	5.000000 	-537.800000 	17.077339 	4.976205 	2.472548 	8.134003 	-10.545098 	1.377600
74.600000 	5.000000 	5.000000 	-537.700000 	18.132347 	4.980157 	2.473427 	8.636507 	-10.543137 	1.377600
75.100000 	5.000000 	5.000000 	-537.800000 	17.836550 	4.975981 	2.473181 	8.495618 	-10.545098 	1.377600
75.600000 	5.000000 	5.000000 	-537.600000 	18.615482 	4.971955 	2.473830 	8.866626 	-10.541176 	1.377600
76.100000 	5.000000 	5.000000 	-538.300000 	18.270386 	4.971508 	2.473542 	8.702256 	-10.554902 	1.377600
76.600000 	5.000000 	5.000000 	-538.100000 	18.329545 	4.972105 	2.473591 	8.730434 	-10.550980 	1.377600
77.100000 	5.000000 	5.000000 	-537.900000 	17.925290 	4.972030 	2.473255 	8.537885 	-10.547059 	1.377600
77.600000 	5.000000 	5.000000 	-538.100000 	18.260526 	4.979560 	2.473534 	8.697559 	-10.550980 	1.377600
78.100000 	5.000000 	5.000000 	-538.400000 	18.625342 	4.976503 	2.473838 	8.871323 	-10.556863 	1.377600
78.600000 	5.000000 	5.000000 	-538.700000 	18.901419 	4.974490 	2.474068 	9.002819 	-10.562745 	1.377600
79.100000 	5.000000 	5.000000 	-539.000000 	18.447864 	4.977249 	2.473690 	8.786789 	-10.568627 	1.377600
79.600000 	5.000000 	5.000000 	-538.700000 	18.585902 	4.981797 	2.473805 	8.852537 	-10.562745 	1.377600
80.100000 	5.000000 	5.000000 	-538.500000 	18.684501 	4.975236 	2.473887 	8.899501 	-10.558824 	1.377600
80.600000 	5.000000 	5.000000 	-538.400000 	18.290106 	4.979933 	2.473559 	8.711648 	-10.556863 	1.377600
81.100000 	5.000000 	5.000000 	-538.300000 	18.378845 	4.970241 	2.473633 	8.753915 	-10.554902 	1.377600
81.600000 	5.000000 	5.000000 	-538.200000 	19.591612 	4.976205 	2.474643 	9.331561 	-10.552941 	1.377600
82.100000 	5.000000 	5.000000 	-538.000000 	19.295815 	4.975310 	2.474397 	9.190672 	-10.549020 	1.377600
82.600000 	5.000000 	5.000000 	-538.500000 	19.759230 	4.981424 	2.474783 	9.411398 	-10.558824 	1.377600
83.100000 	5.000000 	5.000000 	-538.200000 	20.400123 	4.972403 	2.475317 	9.716658 	-10.552941 	1.377600
83.600000 	5.000000 	5.000000 	-538.100000 	20.301524 	4.973223 	2.475235 	9.669695 	-10.550980 	1.377600
84.100000 	5.000000 	5.000000 	-537.900000 	20.055027 	4.975683 	2.475029 	9.552287 	-10.547059 	1.377600
84.600000 	5.000000 	5.000000 	-537.500000 	21.277654 	4.977771 	2.476048 	10.134629 	-10.539216 	1.377600
85.100000 	5.000000 	5.000000 	-536.800000 	23.890526 	4.975683 	2.478226 	11.379150 	-10.525490 	1.377600
85.600000 	5.000000 	5.000000 	-535.900000 	26.049843 	4.973372 	2.480025 	12.407641 	-10.507843 	1.377600
86.100000 	5.000000 	5.000000 	-534.600000 	31.305167 	4.979336 	2.484404 	14.910773 	-10.482353 	1.377600
86.600000 	5.000000 	5.000000 	-533.000000 	36.471752 	4.970166 	2.488710 	17.371637 	-10.450980 	1.377600
87.100000 	5.000000 	5.000000 	-531.000000 	43.837094 	4.980082 	2.494848 	20.879778 	-10.411765 	1.377600
87.600000 	5.000000 	5.000000 	-528.900000 	52.385623 	4.976652 	2.501972 	24.951475 	-10.370588 	1.377600
88.100000 	5.000000 	5.000000 	-526.400000 	60.253819 	4.969421 	2.508528 	28.699128 	-10.321569 	1.377600
88.600000 	5.000000 	5.000000 	-523.700000 	69.423521 	4.979187 	2.516170 	33.066692 	-10.268627 	1.377600
89.100000 	5.000000 	5.000000 	-521.000000 	78.741121 	4.970464 	2.523934 	37.504702 	-10.215686 	1.377600
89.600000 	5.000000 	5.000000 	-518.000000 	89.409527 	4.979336 	2.532825 	42.586105 	-10.156863 	1.377600
90.100000 	5.000000 	5.000000 	-514.900000 	99.289142 	4.984033 	2.541058 	47.291804 	-10.096078 	1.377600
90.600000 	5.000000 	5.000000 	-511.700000 	109.484272 	4.976802 	2.549554 	52.147784 	-10.033333 	1.377600
91.100000 	5.000000 	5.000000 	-508.200000 	120.063939 	4.969570 	2.558370 	57.186920 	-9.964706 	1.377600
91.600000 	5.000000 	5.000000 	-504.900000 	131.018282 	4.976280 	2.567499 	62.404516 	-9.900000 	1.377600
92.100000 	5.000000 	5.000000 	-501.500000 	141.666967 	4.970986 	2.576373 	67.476526 	-9.833333 	1.377600
92.600000 	5.000000 	5.000000 	-498.200000 	152.355093 	4.982020 	2.585279 	72.567322 	-9.768627 	1.377600
93.100000 	5.000000 	5.000000 	-494.700000 	163.082657 	4.974714 	2.594219 	77.676903 	-9.700000 	1.377600
93.600000 	5.000000 	5.000000 	-491.200000 	173.544005 	4.975534 	2.602937 	82.659683 	-9.631373 	1.377600
94.100000 	5.000000 	5.000000 	-487.400000 	184.567366 	4.982244 	2.612123 	87.910153 	-9.556863 	1.377600
94.600000 	5.000000 	5.000000 	-483.600000 	196.152741 	4.975460 	2.621777 	93.428312 	-9.482353 	1.377600
95.100000 	5.000000 	5.000000 	-480.100000 	206.485910 	4.971955 	2.630388 	98.350040 	-9.413725 	1.377600
95.600000 	5.000000 	5.000000 	-476.500000 	217.627589 	4.977323 	2.639673 	103.656866 	-9.343137 	1.377600
96.100000 	5.000000 	5.000000 	-473.000000 	228.976327 	4.980380 	2.649130 	109.062313 	-9.274510 	1.377600
96.600000 	5.000000 	5.000000 	-469.200000 	239.733470 	4.972105 	2.658095 	114.185983 	-9.200000 	1.377600
97.100000 	5.000000 	5.000000 	-465.200000 	250.934309 	4.974938 	2.667429 	119.520985 	-9.121569 	1.377600
97.600000 	5.000000 	5.000000 	-461.500000 	261.888650 	4.976280 	2.676557 	124.738581 	-9.049020 	1.377600
98.100000 	5.000000 	5.000000 	-457.800000 	272.478175 	4.975981 	2.685382 	129.782413 	-8.976471 	1.377600
98.600000 	5.000000 	5.000000 	-454.100000 	283.294478 	4.982542 	2.694396 	134.934260 	-8.903922 	1.377600
99.100000 	5.000000 	5.000000 	-450.200000 	293.913582 	4.975758 	2.703245 	139.992180 	-8.827451 	1.377600
99.600000 	5.000000 	5.000000 	-446.300000 	304.572127 	4.975832 	2.712127 	145.068886 	-8.750980 	1.377600
100.100000 	5.000000 	5.000000 	-442.500000 	315.782824 	4.972179 	2.721469 	150.408585 	-8.676471 	1.377600
100.600000 	5.000000 	5.000000 	-438.900000 	327.220300 	4.966737 	2.731000 	155.856299 	-8.605882 	1.377600
101.100000 	5.000000 	5.000000 	-435.100000 	337.661926 	4.975534 	2.739702 	160.829686 	-8.531373 	1.377600
101.600000 	5.000000 	5.000000 	-431.200000 	348.350049 	4.971135 	2.748609 	165.920481 	-8.454902 	1.377600
102.100000 	5.000000 	5.000000 	-427.300000 	359.038172 	4.975310 	2.757515 	171.011275 	-8.378431 	1.377600
102.600000 	5.000000 	5.000000 	-423.300000 	369.834754 	4.975087 	2.766512 	176.153729 	-8.300000 	1.377600
103.100000 	5.000000 	5.000000 	-419.500000 	380.779234 	4.969122 	2.775633 	181.366627 	-8.225490 	1.377600
103.600000 	5.000000 	5.000000 	-415.700000 	391.644835 	4.974714 	2.784688 	186.541955 	-8.150980 	1.377600
104.100000 	5.000000 	5.000000 	-411.700000 	402.875252 	4.974416 	2.794046 	191.891046 	-8.072549 	1.377600
104.600000 	5.000000 	5.000000 	-407.600000 	413.839451 	4.974043 	2.803183 	197.113337 	-7.992157 	1.377600
105.100000 	5.000000 	5.000000 	-403.600000 	424.064159 	4.972999 	2.811704 	201.983405 	-7.913725 	1.377600
105.600000 	5.000000 	5.000000 	-399.800000 	434.466344 	4.973596 	2.820372 	206.938006 	-7.839216 	1.377600
106.100000 	5.000000 	5.000000 	-396.000000 	445.460123 	4.973745 	2.829534 	212.174386 	-7.764706 	1.377600
106.600000 	5.000000 	5.000000 	-392.100000 	455.310155 	4.973596 	2.837742 	216.865994 	-7.688235 	1.377600
107.100000 	5.000000 	5.000000 	-388.100000 	466.175755 	4.981573 	2.846797 	222.041322 	-7.609804 	1.377600
107.600000 	5.000000 	5.000000 	-384.200000 	476.755418 	4.971583 	2.855613 	227.080456 	-7.533333 	1.377600
108.100000 	5.000000 	5.000000 	-380.200000 	487.512559 	4.973223 	2.864577 	232.204124 	-7.454902 	1.377600
108.600000 	5.000000 	5.000000 	-376.200000 	497.540068 	4.974043 	2.872934 	236.980266 	-7.376471 	1.377600
109.100000 	5.000000 	5.000000 	-372.100000 	508.100011 	4.974789 	2.881733 	242.010007 	-7.296078 	1.377600
109.600000 	5.000000 	5.000000 	-368.100000 	518.216258 	4.970315 	2.890164 	246.828416 	-7.217647 	1.377600
110.100000 	5.000000 	5.000000 	-364.100000 	528.342366 	4.972701 	2.898602 	251.651520 	-7.139216 	1.377600
110.600000 	5.000000 	5.000000 	-360.200000 	538.941748 	4.977622 	2.907435 	256.700047 	-7.062745 	1.377600
111.100000 	5.000000 	5.000000 	-356.400000 	549.008696 	4.968526 	2.915824 	261.494973 	-6.988235 	1.377600
111.600000 	5.000000 	5.000000 	-352.700000 	558.760127 	4.975161 	2.923950 	266.139618 	-6.915686 	1.377600
112.100000 	5.000000 	5.000000 	-348.700000 	568.777776 	4.973894 	2.932298 	270.911063 	-6.837255 	1.377600
112.600000 	5.000000 	5.000000 	-344.600000 	579.081361 	4.969495 	2.940885 	275.818700 	-6.756863 	1.377600
113.100000 	5.000000 	5.000000 	-340.400000 	589.325786 	4.964947 	2.949422 	280.698160 	-6.674510 	1.377600
113.600000 	5.000000 	5.000000 	-336.300000 	599.777269 	4.969644 	2.958131 	285.676242 	-6.594118 	1.377600
114.100000 	5.000000 	5.000000 	-332.300000 	609.942816 	4.974341 	2.966603 	290.518131 	-6.515686 	1.377600
114.600000 	5.000000 	5.000000 	-328.500000 	619.516768 	4.976503 	2.974581 	295.078242 	-6.441176 	1.377600
115.100000 	5.000000 	5.000000 	-324.400000 	629.849932 	4.972477 	2.983192 	299.999968 	-6.360784 	1.377600
115.600000 	5.000000 	5.000000 	-320.300000 	639.956319 	4.968824 	2.991614 	304.813679 	-6.280392 	1.377600
116.100000 	5.000000 	5.000000 	-316.300000 	649.520411 	4.970763 	2.999584 	309.369093 	-6.201961 	1.377600
116.600000 	5.000000 	5.000000 	-312.200000 	659.804275 	4.974863 	3.008154 	314.267338 	-6.121569 	1.377600
117.100000 	5.000000 	5.000000 	-308.200000 	669.575425 	4.976131 	3.016296 	318.921374 	-6.043137 	1.377600
117.600000 	5.000000 	5.000000 	-304.300000 	679.464894 	4.975758 	3.024538 	323.631767 	-5.966667 	1.377600
118.100000 	5.000000 	5.000000 	-300.300000 	689.186744 	4.972626 	3.032639 	328.262322 	-5.888235 	1.377600
118.600000 	5.000000 	5.000000 	-296.200000 	698.346581 	4.963903 	3.040272 	332.625187 	-5.807843 	1.377600
119.100000 	5.000000 	5.000000 	-292.000000 	708.098010 	4.975832 	3.048398 	337.269831 	-5.725490 	1.377600
119.600000 	5.000000 	5.000000 	-287.800000 	717.908599 	4.973148 	3.056574 	341.942653 	-5.643137 	1.377600
120.100000 	5.000000 	5.000000 	-283.700000 	727.117735 	4.971583 	3.064248 	346.329000 	-5.562745 	1.377600
120.600000 	5.000000 	5.000000 	-279.600000 	736.593087 	4.977920 	3.072144 	350.842147 	-5.482353 	1.377600
121.100000 	5.000000 	5.000000 	-275.500000 	746.393816 	4.978740 	3.080312 	355.510272 	-5.401961 	1.377600
121.600000 	5.000000 	5.000000 	-271.400000 	755.336734 	4.975534 	3.087764 	359.769819 	-5.321569 	1.377600
122.100000 	5.000000 	5.000000 	-267.200000 	764.743067 	4.980306 	3.095603 	364.250092 	-5.239216 	1.377600
122.600000 	5.000000 	5.000000 	-263.100000 	774.622675 	4.976802 	3.103836 	368.955787 	-5.158824 	1.377600
123.100000 	5.000000 	5.000000 	-259.100000 	783.092318 	4.977100 	3.110894 	372.989911 	-5.080392 	1.377600
123.600000 	5.000000 	5.000000 	-255.100000 	792.646549 	4.972776 	3.118856 	377.540628 	-5.001961 	1.377600
124.100000 	5.000000 	5.000000 	-251.400000 	801.362690 	4.969122 	3.126119 	381.692160 	-4.929412 	1.377600
124.600000 	5.000000 	5.000000 	-247.100000 	810.670423 	4.976802 	3.133876 	386.125469 	-4.845098 	1.377600
125.100000 	5.000000 	5.000000 	-242.700000 	819.711940 	4.976429 	3.141410 	390.431979 	-4.758824 	1.377600
125.600000 	5.000000 	5.000000 	-238.500000 	828.960514 	4.978665 	3.149117 	394.837111 	-4.676471 	1.377600
126.100000 	5.000000 	5.000000 	-234.200000 	837.558335 	4.965842 	3.156282 	398.932286 	-4.592157 	1.377600
126.600000 	5.000000 	5.000000 	-230.200000 	846.984387 	4.973074 	3.164137 	403.421951 	-4.513725 	1.377600
127.100000 	5.000000 	5.000000 	-226.000000 	856.124502 	4.976131 	3.171754 	407.775424 	-4.431373 	1.377600
127.600000 	5.000000 	5.000000 	-221.600000 	864.584284 	4.969197 	3.178804 	411.804851 	-4.345098 	1.377600
128.100000 	5.000000 	5.000000 	-217.200000 	873.517342 	4.974639 	3.186248 	416.059701 	-4.258824 	1.377600
128.600000 	5.000000 	5.000000 	-212.900000 	881.937685 	4.970912 	3.193265 	420.070343 	-4.174510 	1.377600
129.100000 	5.000000 	5.000000 	-208.700000 	890.831302 	4.969048 	3.200676 	424.306407 	-4.092157 	1.377600
129.600000 	5.000000 	5.000000 	-204.600000 	898.630472 	4.974192 	3.207176 	428.021182 	-4.011765 	1.377600
130.100000 	5.000000 	5.000000 	-200.600000 	906.745158 	4.975012 	3.213938 	431.886239 	-3.933333 	1.377600
130.600000 	5.000000 	5.000000 	-196.600000 	914.948583 	4.976951 	3.220774 	435.793562 	-3.854902 	1.377600
131.100000 	5.000000 	5.000000 	-192.600000 	923.664722 	4.972626 	3.228037 	439.945093 	-3.776471 	1.377600
131.600000 	5.000000 	5.000000 	-188.300000 	932.104784 	4.964351 	3.235071 	443.965127 	-3.692157 	1.377600
132.100000 	5.000000 	5.000000 	-184.300000 	939.963113 	4.976802 	3.241619 	447.708080 	-3.613725 	1.377600
132.600000 	5.000000 	5.000000 	-180.000000 	949.113087 	4.974938 	3.249244 	452.066248 	-3.529412 	1.377600
133.100000 	5.000000 	5.000000 	-175.700000 	957.750346 	4.978442 	3.256442 	456.180208 	-3.445098 	1.377600
133.600000 	5.000000 	5.000000 	-171.300000 	965.648115 	4.976280 	3.263024 	459.941946 	-3.358824 	1.377600
134.100000 	5.000000 	5.000000 	-167.100000 	974.383973 	4.970092 	3.270303 	464.102869 	-3.276471 	1.377600
134.600000 	5.000000 	5.000000 	-163.100000 	982.429639 	4.971806 	3.277008 	467.935051 	-3.198039 	1.377600
135.100000 	5.000000 	5.000000 	-158.900000 	991.135917 	4.979113 	3.284263 	472.081885 	-3.115686 	1.377600
135.600000 	5.000000 	5.000000 	-154.400000 	999.842196 	4.975609 	3.291519 	476.228719 	-3.027451 	1.377600
136.100000 	5.000000 	5.000000 	-150.000000 	1007.966741 	4.970166 	3.298289 	480.098471 	-2.941176 	1.377600
136.600000 	5.000000 	5.000000 	-145.500000 	1015.736330 	4.970688 	3.304764 	483.799157 	-2.852941 	1.377600
137.100000 	5.000000 	5.000000 	-141.200000 	1023.653817 	4.970166 	3.311362 	487.570287 	-2.768627 	1.377600
137.600000 	5.000000 	5.000000 	-136.900000 	1031.216348 	4.974490 	3.317664 	491.172350 	-2.684314 	1.377600
138.100000 	5.000000 	5.000000 	-132.600000 	1038.502803 	4.976802 	3.323736 	494.642916 	-2.600000 	1.377600
138.600000 	5.000000 	5.000000 	-128.300000 	1046.854125 	4.970837 	3.330695 	498.620683 	-2.515686 	1.377600
139.100000 	5.000000 	5.000000 	-124.000000 	1054.249038 	4.972850 	3.336858 	502.142909 	-2.431373 	1.377600
139.600000 	5.000000 	5.000000 	-119.800000 	1061.249555 	4.975534 	3.342691 	505.477283 	-2.349020 	1.377600
140.100000 	5.000000 	5.000000 	-115.500000 	1067.254225 	4.974118 	3.347695 	508.337330 	-2.264706 	1.377600
140.600000 	5.000000 	5.000000 	-111.300000 	1073.820907 	4.980231 	3.353168 	511.465067 	-2.182353 	1.377600
141.100000 	5.000000 	5.000000 	-107.200000 	1080.003054 	4.972105 	3.358319 	514.409647 	-2.101961 	1.377600
141.600000 	5.000000 	5.000000 	-103.000000 	1085.554169 	4.970763 	3.362945 	517.053665 	-2.019608 	1.377600
142.100000 	5.000000 	5.000000 	-98.800000 	1090.661588 	4.964724 	3.367201 	519.486348 	-1.937255 	1.377600
142.600000 	5.000000 	5.000000 	-94.500000 	1095.246434 	4.973968 	3.371022 	521.670128 	-1.852941 	1.377600
143.100000 	5.000000 	5.000000 	-90.200000 	1099.476324 	4.968526 	3.374547 	523.684841 	-1.768627 	1.377600
143.600000 	5.000000 	5.000000 	-86.000000 	1102.789245 	4.974714 	3.377308 	525.262798 	-1.686275 	1.377600
144.100000 	5.000000 	5.000000 	-81.800000 	1105.757070 	4.970912 	3.379781 	526.676385 	-1.603922 	1.377600
144.600000 	5.000000 	5.000000 	-77.600000 	1107.886805 	4.971210 	3.381556 	527.690786 	-1.521569 	1.377600
145.100000 	5.000000 	5.000000 	-73.300000 	1110.874349 	4.966886 	3.384045 	529.113765 	-1.437255 	1.377600
145.600000 	5.000000 	5.000000 	-68.900000 	1112.688568 	4.975907 	3.385557 	529.977884 	-1.350980 	1.377600
146.100000 	5.000000 	5.000000 	-64.500000 	1113.723856 	4.972552 	3.386420 	530.470996 	-1.264706 	1.377600
146.600000 	5.000000 	5.000000 	-60.100000 	1115.005640 	4.975012 	3.387488 	531.081515 	-1.178431 	1.377600
147.100000 	5.000000 	5.000000 	-55.700000 	1115.656393 	4.977025 	3.388030 	531.391471 	-1.092157 	1.377600
147.600000 	5.000000 	5.000000 	-51.100000 	1116.721260 	4.970613 	3.388918 	531.898671 	-1.001961 	1.377600
148.100000 	5.000000 	5.000000 	-46.600000 	1116.987477 	4.976727 	3.389140 	532.025471 	-0.913725 	1.377600
148.600000 	5.000000 	5.000000 	-41.900000 	1117.746688 	4.972850 	3.389772 	532.387086 	-0.821569 	1.377600
149.100000 	5.000000 	5.000000 	-37.000000 	1118.752396 	4.972552 	3.390610 	532.866109 	-0.725490 	1.377600
149.600000 	5.000000 	5.000000 	-32.100000 	1119.383429 	4.968675 	3.391136 	533.166672 	-0.629412 	1.377600
150.100000 	5.000000 	5.000000 	-27.200000 	1119.787684 	4.972105 	3.391473 	533.359221 	-0.533333 	1.377600
150.600000 	5.000000 	5.000000 	-22.300000 	1119.975022 	4.973670 	3.391629 	533.448450 	-0.437255 	1.377600
151.100000 	5.000000 	5.000000 	-17.400000 	1120.251098 	4.977100 	3.391859 	533.579947 	-0.341176 	1.377600
151.600000 	5.000000 	5.000000 	-12.500000 	1120.724373 	4.975012 	3.392254 	533.805369 	-0.245098 	1.377600
152.100000 	5.000000 	5.000000 	-7.500000 	1121.256806 	4.970912 	3.392697 	534.058969 	-0.147059 	1.377600
152.600000 	5.000000 	5.000000 	-2.400000 	1121.434284 	4.972552 	3.392845 	534.143503 	-0.047059 	1.377600
153.100000 	5.000000 	5.000000 	2.700000 	1121.996298 	4.973074 	3.393314 	534.411192 	0.052941 	1.377600
153.600000 	5.000000 	5.000000 	7.600000 	1121.454004 	4.980977 	3.392862 	534.152895 	0.149020 	1.377600
154.100000 	5.000000 	5.000000 	12.700000 	1121.887839 	4.975907 	3.393223 	534.359533 	0.249020 	1.377600
154.600000 	5.000000 	5.000000 	17.800000 	1122.321674 	4.969793 	3.393585 	534.566170 	0.349020 	1.377600
155.100000 	5.000000 	5.000000 	22.700000 	1122.380833 	4.972328 	3.393634 	534.594348 	0.445098 	1.377600
155.600000 	5.000000 	5.000000 	27.600000 	1122.676630 	4.968228 	3.393881 	534.735237 	0.541176 	1.377600
156.100000 	5.000000 	5.000000 	32.500000 	1122.775228 	4.977920 	3.393963 	534.782200 	0.637255 	1.377600
156.600000 	5.000000 	5.000000 	37.500000 	1122.923127 	4.974416 	3.394086 	534.852644 	0.735294 	1.377600
157.100000 	5.000000 	5.000000 	42.200000 	1122.735789 	4.972403 	3.393930 	534.763415 	0.827451 	1.377600
157.600000 	5.000000 	5.000000 	46.800000 	1122.647050 	4.970464 	3.393856 	534.721148 	0.917647 	1.377600
158.100000 	5.000000 	5.000000 	51.400000 	1122.114616 	4.970986 	3.393412 	534.467548 	1.007843 	1.377600
158.600000 	5.000000 	5.000000 	56.300000 	1122.282234 	4.972925 	3.393552 	534.547385 	1.103922 	1.377600
159.100000 	5.000000 	5.000000 	61.200000 	1122.548451 	4.974043 	3.393774 	534.674185 	1.200000 	1.377600
159.600000 	5.000000 	5.000000 	65.900000 	1122.449852 	4.970390 	3.393692 	534.627222 	1.292157 	1.377600
160.100000 	5.000000 	5.000000 	70.600000 	1122.390693 	4.976205 	3.393642 	534.599044 	1.384314 	1.377600
160.600000 	5.000000 	5.000000 	75.000000 	1121.937138 	4.971583 	3.393264 	534.383014 	1.470588 	1.377600
161.100000 	5.000000 	5.000000 	79.800000 	1121.937138 	4.968824 	3.393264 	534.383014 	1.564706 	1.377600
161.600000 	5.000000 	5.000000 	84.500000 	1121.838539 	4.965618 	3.393182 	534.336051 	1.656863 	1.377600
162.100000 	5.000000 	5.000000 	89.200000 	1121.749801 	4.968079 	3.393108 	534.293784 	1.749020 	1.377600
162.600000 	5.000000 	5.000000 	93.900000 	1122.124476 	4.971061 	3.393421 	534.472244 	1.841176 	1.377600
163.100000 	5.000000 	5.000000 	98.700000 	1122.144196 	4.966215 	3.393437 	534.481637 	1.935294 	1.377600
163.600000 	5.000000 	5.000000 	103.700000 	1121.956858 	4.962263 	3.393281 	534.392407 	2.033333 	1.377600
164.100000 	5.000000 	5.000000 	108.600000 	1121.818820 	4.976131 	3.393166 	534.326659 	2.129412 	1.377600
164.600000 	5.000000 	5.000000 	113.500000 	1121.444144 	4.966587 	3.392854 	534.148199 	2.225490 	1.377600
165.100000 	5.000000 	5.000000 	118.600000 	1120.517315 	4.977622 	3.392081 	533.706747 	2.325490 	1.377600
165.600000 	5.000000 	5.000000 	123.500000 	1120.783532 	4.967929 	3.392303 	533.833547 	2.421569 	1.377600
166.100000 	5.000000 	5.000000 	128.500000 	1120.260958 	4.972626 	3.391868 	533.584643 	2.519608 	1.377600
166.600000 	5.000000 	5.000000 	133.600000 	1120.438436 	4.976205 	3.392016 	533.669177 	2.619608 	1.377600
167.100000 	5.000000 	5.000000 	138.900000 	1119.945442 	4.970539 	3.391605 	533.434361 	2.723529 	1.377600
167.600000 	5.000000 	5.000000 	144.100000 	1119.274970 	4.974267 	3.391046 	533.115013 	2.825490 	1.377600
168.100000 	5.000000 	5.000000 	149.200000 	1119.353849 	4.977398 	3.391112 	533.152583 	2.925490 	1.377600
168.600000 	5.000000 	5.000000 	154.200000 	1119.008753 	4.975460 	3.390824 	532.988213 	3.023529 	1.377600
169.100000 	5.000000 	5.000000 	159.100000 	1118.565058 	4.975236 	3.390454 	532.776879 	3.119608 	1.377600
169.600000 	5.000000 	5.000000 	164.000000 	1117.243834 	4.972925 	3.389353 	532.147575 	3.215686 	1.377600
170.100000 	5.000000 	5.000000 	169.100000 	1117.342433 	4.969719 	3.389436 	532.194538 	3.315686 	1.377600
170.600000 	5.000000 	5.000000 	174.300000 	1117.026917 	4.975981 	3.389173 	532.044256 	3.417647 	1.377600
171.100000 	5.000000 	5.000000 	179.500000 	1116.336725 	4.971135 	3.388597 	531.715515 	3.519608 	1.377600
171.600000 	5.000000 	5.000000 	184.500000 	1115.242278 	4.976056 	3.387685 	531.194226 	3.617647 	1.377600
172.100000 	5.000000 	5.000000 	189.300000 	1115.045080 	4.970017 	3.387521 	531.100300 	3.711765 	1.377600
172.600000 	5.000000 	5.000000 	194.100000 	1113.980213 	4.967929 	3.386634 	530.593100 	3.805882 	1.377600
173.100000 	5.000000 	5.000000 	198.800000 	1114.167550 	4.970613 	3.386790 	530.682329 	3.898039 	1.377600
173.600000 	5.000000 	5.000000 	203.600000 	1114.177410 	4.964649 	3.386798 	530.687026 	3.992157 	1.377600
174.100000 	5.000000 	5.000000 	208.300000 	1113.891474 	4.978740 	3.386560 	530.550833 	4.084314 	1.377600
174.600000 	5.000000 	5.000000 	213.200000 	1113.063243 	4.969868 	3.385870 	530.156344 	4.180392 	1.377600
175.100000 	5.000000 	5.000000 	217.900000 	1113.053384 	4.969495 	3.385861 	530.151647 	4.272549 	1.377600
175.600000 	5.000000 	5.000000 	222.500000 	1111.889917 	4.968451 	3.384892 	529.597484 	4.362745 	1.377600
176.100000 	5.000000 	5.000000 	226.900000 	1111.564541 	4.969495 	3.384621 	529.442506 	4.449020 	1.377600
176.600000 	5.000000 	5.000000 	231.500000 	1111.101127 	4.974639 	3.384234 	529.221780 	4.539216 	1.377600
177.100000 	5.000000 	5.000000 	236.400000 	1111.396923 	4.972328 	3.384481 	529.362669 	4.635294 	1.377600
177.600000 	5.000000 	5.000000 	241.500000 	1110.844770 	4.968228 	3.384021 	529.099676 	4.735294 	1.377600
178.100000 	5.000000 	5.000000 	246.600000 	1110.440515 	4.974341 	3.383684 	528.907128 	4.835294 	1.377600
178.600000 	5.000000 	5.000000 	251.600000 	1110.124998 	4.966513 	3.383421 	528.756846 	4.933333 	1.377600
179.100000 	5.000000 	5.000000 	256.500000 	1108.576997 	4.965916 	3.382131 	528.019527 	5.029412 	1.377600
179.600000 	5.000000 	5.000000 	261.400000 	1108.458678 	4.973148 	3.382032 	527.963171 	5.125490 	1.377600
180.100000 	5.000000 	5.000000 	266.500000 	1107.936104 	4.965171 	3.381597 	527.714267 	5.225490 	1.377600
180.600000 	5.000000 	5.000000 	271.500000 	1107.098014 	4.967408 	3.380899 	527.315082 	5.323529 	1.377600
181.100000 	5.000000 	5.000000 	276.200000 	1106.476841 	4.968302 	3.380381 	527.019215 	5.415686 	1.377600
181.600000 	5.000000 	5.000000 	280.800000 	1105.619032 	4.973521 	3.379666 	526.610637 	5.505882 	1.377600
182.100000 	5.000000 	5.000000 	285.700000 	1105.599312 	4.978367 	3.379650 	526.601244 	5.601961 	1.377600
182.600000 	5.000000 	5.000000 	290.600000 	1104.209068 	4.979486 	3.378491 	525.939066 	5.698039 	1.377600
183.100000 	5.000000 	5.000000 	295.800000 	1103.163921 	4.970390 	3.377620 	525.441258 	5.800000 	1.377600
183.600000 	5.000000 	5.000000 	300.800000 	1101.477881 	4.972626 	3.376215 	524.638190 	5.898039 	1.377600
184.100000 	5.000000 	5.000000 	305.700000 	1100.166516 	4.968899 	3.375122 	524.013582 	5.994118 	1.377600
184.600000 	5.000000 	5.000000 	310.700000 	1098.233979 	4.975609 	3.373512 	523.093107 	6.092157 	1.377600
185.100000 	5.000000 	5.000000 	315.700000 	1094.408344 	4.972179 	3.370324 	521.270943 	6.190196 	1.377600
185.600000 	5.000000 	5.000000 	321.000000 	1089.429103 	4.973148 	3.366174 	518.899311 	6.294118 	1.377600
186.100000 	5.000000 	5.000000 	326.400000 	1077.163408 	4.968153 	3.355953 	513.057113 	6.400000 	1.377600
186.600000 	5.000000 	5.000000 	332.900000 	1046.696366 	4.967780 	3.330564 	498.545542 	6.527451 	1.377600
187.100000 	5.000000 	5.000000 	435.700000 	8.982365 	4.973968 	2.465802 	4.278335 	8.543137 	1.377600
187.600000 	5.000000 	5.000000 	435.600000 	9.110543 	4.976056 	2.465909 	4.339387 	8.541176 	1.377600
188.100000 	5.000000 	5.000000 	435.500000 	9.248582 	4.972776 	2.466024 	4.405135 	8.539216 	1.377600
188.600000 	5.000000 	5.000000 	435.500000 	8.726007 	4.970539 	2.465588 	4.156231 	8.539216 	1.377600
189.100000 	5.000000 	5.000000 	435.500000 	9.228862 	4.969868 	2.466008 	4.395743 	8.539216 	1.377600
189.600000 	5.000000 	5.000000 	435.500000 	8.765447 	4.975609 	2.465621 	4.175016 	8.539216 	1.377600
190.100000 	5.000000 	5.000000 	435.500000 	8.824606 	4.972552 	2.465671 	4.203194 	8.539216 	1.377600
190.600000 	5.000000 	5.000000 	435.500000 	9.149983 	4.974863 	2.465942 	4.358172 	8.539216 	1.377600
191.100000 	5.000000 	5.000000 	435.600000 	9.011944 	4.970241 	2.465827 	4.292424 	8.541176 	1.377600
191.600000 	5.000000 	5.000000 	435.600000 	8.647128 	4.972999 	2.465523 	4.118661 	8.541176 	1.377600
192.100000 	5.000000 	5.000000 	435.700000 	8.775307 	4.977323 	2.465630 	4.179713 	8.543137 	1.377600
192.600000 	5.000000 	5.000000 	435.800000 	9.297881 	4.976429 	2.466065 	4.428617 	8.545098 	1.377600
193.100000 	5.000000 	5.000000 	435.900000 	9.080964 	4.971359 	2.465884 	4.325298 	8.547059 	1.377600
193.600000 	5.000000 	5.000000 	435.900000 	9.475359 	4.973596 	2.466213 	4.513150 	8.547059 	1.377600
194.100000 	5.000000 	5.000000 	436.900000 	8.637268 	4.969421 	2.465515 	4.113964 	8.566667 	1.377600
194.600000 	5.000000 	5.000000 	440.300000 	9.426060 	4.972552 	2.466172 	4.489669 	8.633333 	1.377600
195.100000 	5.000000 	5.000000 	443.300000 	9.041524 	2.556061 	2.465851 	4.306513 	8.692157 	1.377600
195.600000 	5.000000 	5.000000 	443.300000 	9.041524 	0.005909 	2.465851 	4.306513 	8.692157 	1.377600
196.000000 	5.000000 	5.000000 	443.400000 	9.228862 	0.007809 	2.466008 	4.395743 	8.694118 	1.377600